
wandb: ERROR Error while calling W&B API: Invalid sweep config: invalid hyperparameter configuration: weight_decay (<Response [400]>)
wandb: ERROR Invalid sweep config: invalid hyperparameter configuration: weight_decay
Traceback (most recent call last):
  File "C:\Users\sophi\AppData\Local\Programs\Python\Python39\lib\site-packages\wandb\sdk\lib\retry.py", line 102, in __call__
    result = self._call_fn(*args, **kwargs)
  File "C:\Users\sophi\AppData\Local\Programs\Python\Python39\lib\site-packages\wandb\sdk\internal\internal_api.py", line 146, in execute
    six.reraise(*sys.exc_info())
  File "C:\Users\sophi\AppData\Local\Programs\Python\Python39\lib\site-packages\six.py", line 719, in reraise
    raise value
  File "C:\Users\sophi\AppData\Local\Programs\Python\Python39\lib\site-packages\wandb\sdk\internal\internal_api.py", line 140, in execute
    return self.client.execute(*args, **kwargs)
  File "C:\Users\sophi\AppData\Local\Programs\Python\Python39\lib\site-packages\wandb\vendor\gql-0.2.0\gql\client.py", line 52, in execute
    result = self._get_result(document, *args, **kwargs)
  File "C:\Users\sophi\AppData\Local\Programs\Python\Python39\lib\site-packages\wandb\vendor\gql-0.2.0\gql\client.py", line 60, in _get_result
    return self.transport.execute(document, *args, **kwargs)
  File "C:\Users\sophi\AppData\Local\Programs\Python\Python39\lib\site-packages\wandb\vendor\gql-0.2.0\gql\transport\requests.py", line 39, in execute
    request.raise_for_status()
  File "C:\Users\sophi\AppData\Local\Programs\Python\Python39\lib\site-packages\requests\models.py", line 960, in raise_for_status
    raise HTTPError(http_error_msg, response=self)
requests.exceptions.HTTPError: 400 Client Error: Bad Request for url: https://api.wandb.ai/graphql
During handling of the above exception, another exception occurred:
Traceback (most recent call last):
  File "C:\Users\sophi\AppData\Local\Programs\Python\Python39\lib\site-packages\wandb\apis\normalize.py", line 24, in wrapper
    return func(*args, **kwargs)
  File "C:\Users\sophi\AppData\Local\Programs\Python\Python39\lib\site-packages\wandb\sdk\internal\internal_api.py", line 1892, in upsert_sweep
    raise (e)
  File "C:\Users\sophi\AppData\Local\Programs\Python\Python39\lib\site-packages\wandb\sdk\internal\internal_api.py", line 1878, in upsert_sweep
    response = self.gql(
  File "C:\Users\sophi\AppData\Local\Programs\Python\Python39\lib\site-packages\wandb\sdk\lib\retry.py", line 118, in __call__
    if not check_retry_fn(e):
  File "C:\Users\sophi\AppData\Local\Programs\Python\Python39\lib\site-packages\wandb\sdk\internal\internal_api.py", line 1869, in no_retry_4xx
    raise UsageError(body["errors"][0]["message"])
wandb.errors.UsageError: Invalid sweep config: invalid hyperparameter configuration: weight_decay
During handling of the above exception, another exception occurred:
Traceback (most recent call last):
  File "C:\Users\sophi\AppData\Local\Programs\Python\Python39\lib\runpy.py", line 197, in _run_module_as_main
    return _run_code(code, main_globals, None,
  File "C:\Users\sophi\AppData\Local\Programs\Python\Python39\lib\runpy.py", line 87, in _run_code
    exec(code, run_globals)
  File "c:\program files\microsoft visual studio\2022\community\common7\ide\extensions\microsoft\python\core\debugpy\__main__.py", line 45, in <module>
    cli.main()
  File "c:\program files\microsoft visual studio\2022\community\common7\ide\extensions\microsoft\python\core\debugpy/..\debugpy\server\cli.py", line 444, in main
    run()
  File "c:\program files\microsoft visual studio\2022\community\common7\ide\extensions\microsoft\python\core\debugpy/..\debugpy\server\cli.py", line 285, in run_file
    runpy.run_path(target_as_str, run_name=compat.force_str("__main__"))
  File "C:\Users\sophi\AppData\Local\Programs\Python\Python39\lib\runpy.py", line 268, in run_path
    return _run_module_code(code, init_globals, run_name,
  File "C:\Users\sophi\AppData\Local\Programs\Python\Python39\lib\runpy.py", line 97, in _run_module_code
    _run_code(code, mod_globals, init_globals,
  File "C:\Users\sophi\AppData\Local\Programs\Python\Python39\lib\runpy.py", line 87, in _run_code
    exec(code, run_globals)
  File "C:\Users\sophi\SeaIceExtent\SeaIce\unet\tune_hyperparameters.py", line 191, in <module>
    sweep_id = wandb.sweep(sweep_config, project=model_name + "hyp-sweep")
  File "C:\Users\sophi\AppData\Local\Programs\Python\Python39\lib\site-packages\wandb\sdk\wandb_sweep.py", line 105, in sweep
    sweep_id, warnings = api.upsert_sweep(sweep)
  File "C:\Users\sophi\AppData\Local\Programs\Python\Python39\lib\site-packages\wandb\apis\internal.py", line 99, in upsert_sweep
    return self.api.upsert_sweep(*args, **kwargs)
  File "C:\Users\sophi\AppData\Local\Programs\Python\Python39\lib\site-packages\wandb\apis\normalize.py", line 62, in wrapper
    six.reraise(CommError, CommError(message, err), sys.exc_info()[2])
  File "C:\Users\sophi\AppData\Local\Programs\Python\Python39\lib\site-packages\six.py", line 718, in reraise
    raise value.with_traceback(tb)
  File "C:\Users\sophi\AppData\Local\Programs\Python\Python39\lib\site-packages\wandb\apis\normalize.py", line 24, in wrapper
    return func(*args, **kwargs)
  File "C:\Users\sophi\AppData\Local\Programs\Python\Python39\lib\site-packages\wandb\sdk\internal\internal_api.py", line 1892, in upsert_sweep
    raise (e)
  File "C:\Users\sophi\AppData\Local\Programs\Python\Python39\lib\site-packages\wandb\sdk\internal\internal_api.py", line 1878, in upsert_sweep
    response = self.gql(
  File "C:\Users\sophi\AppData\Local\Programs\Python\Python39\lib\site-packages\wandb\sdk\lib\retry.py", line 118, in __call__
    if not check_retry_fn(e):
  File "C:\Users\sophi\AppData\Local\Programs\Python\Python39\lib\site-packages\wandb\sdk\internal\internal_api.py", line 1869, in no_retry_4xx
    raise UsageError(body["errors"][0]["message"])
wandb.errors.CommError: Invalid sweep config: invalid hyperparameter configuration: weight_decay