2022-03-07 18:04:00,906 INFO    MainThread:7884 [internal.py:wandb_internal():89] W&B internal server running at pid: 7884, started at: 2022-03-07 18:04:00.905636
2022-03-07 18:04:00,908 DEBUG   HandlerThread:7884 [handler.py:handle_request():131] handle_request: check_version
2022-03-07 18:04:00,908 INFO    WriterThread:7884 [datastore.py:open_for_write():77] open: C:\Users\sophi\SeaIceExtent\SeaIce\wandb\run-20220307_180359-2m59cwrk\run-2m59cwrk.wandb
2022-03-07 18:04:00,911 DEBUG   SenderThread:7884 [sender.py:send():235] send: header
2022-03-07 18:04:00,911 DEBUG   SenderThread:7884 [sender.py:send_request():249] send_request: check_version
2022-03-07 18:04:01,057 DEBUG   SenderThread:7884 [sender.py:send():235] send: run
2022-03-07 18:04:01,059 INFO    SenderThread:7884 [sender.py:_maybe_setup_resume():489] checking resume status for None/test-hyptuning/2m59cwrk
2022-03-07 18:04:01,442 ERROR   SenderThread:7884 [internal_api.py:execute():143] 401 response executing GraphQL.
2022-03-07 18:04:01,442 ERROR   SenderThread:7884 [internal_api.py:execute():144] {"errors":[{"message":"permission denied","path":["upsertBucket"],"extensions":{"code":"PERMISSION_ERROR"}}],"data":{"upsertBucket":null}}
2022-03-07 18:04:02,067 INFO    WriterThread:7884 [datastore.py:close():281] close: C:\Users\sophi\SeaIceExtent\SeaIce\wandb\run-20220307_180359-2m59cwrk\run-2m59cwrk.wandb
2022-03-07 18:04:02,067 INFO    HandlerThread:7884 [handler.py:finish():739] shutting down handler
2022-03-07 18:04:02,068 ERROR   MainThread:7884 [internal.py:wandb_internal():164] Thread SenderThread:
Traceback (most recent call last):
  File "C:\Users\sophi\AppData\Local\Programs\Python\Python39\lib\site-packages\wandb\sdk\lib\retry.py", line 102, in __call__
    result = self._call_fn(*args, **kwargs)
  File "C:\Users\sophi\AppData\Local\Programs\Python\Python39\lib\site-packages\wandb\sdk\internal\internal_api.py", line 146, in execute
    six.reraise(*sys.exc_info())
  File "C:\Users\sophi\AppData\Local\Programs\Python\Python39\lib\site-packages\six.py", line 719, in reraise
    raise value
  File "C:\Users\sophi\AppData\Local\Programs\Python\Python39\lib\site-packages\wandb\sdk\internal\internal_api.py", line 140, in execute
    return self.client.execute(*args, **kwargs)
  File "C:\Users\sophi\AppData\Local\Programs\Python\Python39\lib\site-packages\wandb\vendor\gql-0.2.0\gql\client.py", line 52, in execute
    result = self._get_result(document, *args, **kwargs)
  File "C:\Users\sophi\AppData\Local\Programs\Python\Python39\lib\site-packages\wandb\vendor\gql-0.2.0\gql\client.py", line 60, in _get_result
    return self.transport.execute(document, *args, **kwargs)
  File "C:\Users\sophi\AppData\Local\Programs\Python\Python39\lib\site-packages\wandb\vendor\gql-0.2.0\gql\transport\requests.py", line 39, in execute
    request.raise_for_status()
  File "C:\Users\sophi\AppData\Local\Programs\Python\Python39\lib\site-packages\requests\models.py", line 960, in raise_for_status
    raise HTTPError(http_error_msg, response=self)
requests.exceptions.HTTPError: 401 Client Error: Unauthorized for url: https://api.wandb.ai/graphql

During handling of the above exception, another exception occurred:

Traceback (most recent call last):
  File "C:\Users\sophi\AppData\Local\Programs\Python\Python39\lib\site-packages\wandb\apis\normalize.py", line 24, in wrapper
    return func(*args, **kwargs)
  File "C:\Users\sophi\AppData\Local\Programs\Python\Python39\lib\site-packages\wandb\sdk\internal\internal_api.py", line 1296, in upsert_run
    response = self.gql(mutation, variable_values=variable_values, **kwargs)
  File "C:\Users\sophi\AppData\Local\Programs\Python\Python39\lib\site-packages\wandb\sdk\lib\retry.py", line 118, in __call__
    if not check_retry_fn(e):
  File "C:\Users\sophi\AppData\Local\Programs\Python\Python39\lib\site-packages\wandb\util.py", line 817, in no_retry_auth
    raise CommError("Invalid or missing api_key.  Run wandb login")
wandb.errors.CommError: Invalid or missing api_key.  Run wandb login

During handling of the above exception, another exception occurred:

Traceback (most recent call last):
  File "C:\Users\sophi\AppData\Local\Programs\Python\Python39\lib\site-packages\wandb\sdk\internal\internal_util.py", line 54, in run
    self._run()
  File "C:\Users\sophi\AppData\Local\Programs\Python\Python39\lib\site-packages\wandb\sdk\internal\internal_util.py", line 105, in _run
    self._process(record)
  File "C:\Users\sophi\AppData\Local\Programs\Python\Python39\lib\site-packages\wandb\sdk\internal\internal.py", line 305, in _process
    self._sm.send(record)
  File "C:\Users\sophi\AppData\Local\Programs\Python\Python39\lib\site-packages\wandb\sdk\internal\sender.py", line 237, in send
    send_handler(record)
  File "C:\Users\sophi\AppData\Local\Programs\Python\Python39\lib\site-packages\wandb\sdk\internal\sender.py", line 692, in send_run
    self._init_run(run, config_value_dict)
  File "C:\Users\sophi\AppData\Local\Programs\Python\Python39\lib\site-packages\wandb\sdk\internal\sender.py", line 716, in _init_run
    server_run, inserted = self._api.upsert_run(
  File "C:\Users\sophi\AppData\Local\Programs\Python\Python39\lib\site-packages\wandb\apis\normalize.py", line 62, in wrapper
    six.reraise(CommError, CommError(message, err), sys.exc_info()[2])
  File "C:\Users\sophi\AppData\Local\Programs\Python\Python39\lib\site-packages\six.py", line 718, in reraise
    raise value.with_traceback(tb)
  File "C:\Users\sophi\AppData\Local\Programs\Python\Python39\lib\site-packages\wandb\apis\normalize.py", line 24, in wrapper
    return func(*args, **kwargs)
  File "C:\Users\sophi\AppData\Local\Programs\Python\Python39\lib\site-packages\wandb\sdk\internal\internal_api.py", line 1296, in upsert_run
    response = self.gql(mutation, variable_values=variable_values, **kwargs)
  File "C:\Users\sophi\AppData\Local\Programs\Python\Python39\lib\site-packages\wandb\sdk\lib\retry.py", line 118, in __call__
    if not check_retry_fn(e):
  File "C:\Users\sophi\AppData\Local\Programs\Python\Python39\lib\site-packages\wandb\util.py", line 817, in no_retry_auth
    raise CommError("Invalid or missing api_key.  Run wandb login")
wandb.errors.CommError: Invalid or missing api_key.  Run wandb login
2022-03-07 18:04:04,083 INFO    MainThread:7884 [internal.py:handle_exit():79] Internal process exited
